<?xml version="1.0" encoding="UTF-8"?>
<!-- Generated by org.testng.reporters.JUnitReportReporter -->
<testsuite name="CommandTest.CommandCheckContainsTest" tests="12" time="3.376" ignored="0" failures="4" timestamp="07 мар 2017 09:20:30 GMT" skipped="0" hostname="Pk" errors="5">
  <testcase name="commandWithTimer_Test_ValidArguments_Positive" time="0.074" classname="CommandTest.CommandCheckContainsTest">
    <failure type="java.lang.AssertionError" message="expected [+ [checkPageContains &quot;Software Automation Tester&quot;] 0,000] but found [+ [checkPageContainsText &quot;Software Automation Tester&quot;] 0,000]">
      <![CDATA[java.lang.AssertionError: expected [+ [checkPageContains "Software Automation Tester"] 0,000] but found [+ [checkPageContainsText "Software Automation Tester"] 0,000]
	at org.testng.Assert.fail(Assert.java:94)
	at org.testng.Assert.failNotEquals(Assert.java:513)
	at org.testng.Assert.assertEqualsImpl(Assert.java:135)
	at org.testng.Assert.assertEquals(Assert.java:116)
	at org.testng.Assert.assertEquals(Assert.java:179)
	at CommandTest.CommandCheckContainsTest.commandWithTimer_Test_ValidArguments_Positive(CommandCheckContainsTest.java:125)
	at sun.reflect.NativeMethodAccessorImpl.invoke0(Native Method)
	at sun.reflect.NativeMethodAccessorImpl.invoke(Unknown Source)
	at sun.reflect.DelegatingMethodAccessorImpl.invoke(Unknown Source)
	at java.lang.reflect.Method.invoke(Unknown Source)
	at org.testng.internal.MethodInvocationHelper.invokeMethod(MethodInvocationHelper.java:104)
	at org.testng.internal.Invoker.invokeMethod(Invoker.java:645)
	at org.testng.internal.Invoker.invokeTestMethod(Invoker.java:851)
	at org.testng.internal.Invoker.invokeTestMethods(Invoker.java:1177)
	at org.testng.internal.TestMethodWorker.invokeTestMethods(TestMethodWorker.java:129)
	at org.testng.internal.TestMethodWorker.run(TestMethodWorker.java:112)
	at org.testng.TestRunner.privateRun(TestRunner.java:756)
	at org.testng.TestRunner.run(TestRunner.java:610)
	at org.testng.SuiteRunner.runTest(SuiteRunner.java:387)
	at org.testng.SuiteRunner.runSequentially(SuiteRunner.java:382)
	at org.testng.SuiteRunner.privateRun(SuiteRunner.java:340)
	at org.testng.SuiteRunner.run(SuiteRunner.java:289)
	at org.testng.SuiteRunnerWorker.runSuite(SuiteRunnerWorker.java:52)
	at org.testng.SuiteRunnerWorker.run(SuiteRunnerWorker.java:86)
	at org.testng.TestNG.runSuitesSequentially(TestNG.java:1293)
	at org.testng.TestNG.runSuitesLocally(TestNG.java:1218)
	at org.testng.TestNG.runSuites(TestNG.java:1133)
	at org.testng.TestNG.run(TestNG.java:1104)
	at org.testng.remote.AbstractRemoteTestNG.run(AbstractRemoteTestNG.java:132)
	at org.testng.remote.RemoteTestNG.initAndRun(RemoteTestNG.java:236)
	at org.testng.remote.RemoteTestNG.main(RemoteTestNG.java:81)
]]>
    </failure>
  </testcase> <!-- commandWithTimer_Test_ValidArguments_Positive -->
  <testcase name="run_Test_ValidSizeParams_ValidArguments_Negative" time="0.069" classname="CommandTest.CommandCheckContainsTest">
    <failure type="java.lang.AssertionError" message="expected [! [checkPageContainsText &quot;I think this page do not have this text&quot;] 0,000] but found [! [checkPageContains &quot;I think this page do not have this text&quot;] 0,000]">
      <![CDATA[java.lang.AssertionError: expected [! [checkPageContainsText "I think this page do not have this text"] 0,000] but found [! [checkPageContains "I think this page do not have this text"] 0,000]
	at org.testng.Assert.fail(Assert.java:94)
	at org.testng.Assert.failNotEquals(Assert.java:513)
	at org.testng.Assert.assertEqualsImpl(Assert.java:135)
	at org.testng.Assert.assertEquals(Assert.java:116)
	at org.testng.Assert.assertEquals(Assert.java:179)
	at CommandTest.CommandCheckContainsTest.run_Test_ValidSizeParams_ValidArguments_Negative(CommandCheckContainsTest.java:69)
	at sun.reflect.NativeMethodAccessorImpl.invoke0(Native Method)
	at sun.reflect.NativeMethodAccessorImpl.invoke(Unknown Source)
	at sun.reflect.DelegatingMethodAccessorImpl.invoke(Unknown Source)
	at java.lang.reflect.Method.invoke(Unknown Source)
	at org.testng.internal.MethodInvocationHelper.invokeMethod(MethodInvocationHelper.java:104)
	at org.testng.internal.Invoker.invokeMethod(Invoker.java:645)
	at org.testng.internal.Invoker.invokeTestMethod(Invoker.java:851)
	at org.testng.internal.Invoker.invokeTestMethods(Invoker.java:1177)
	at org.testng.internal.TestMethodWorker.invokeTestMethods(TestMethodWorker.java:129)
	at org.testng.internal.TestMethodWorker.run(TestMethodWorker.java:112)
	at org.testng.TestRunner.privateRun(TestRunner.java:756)
	at org.testng.TestRunner.run(TestRunner.java:610)
	at org.testng.SuiteRunner.runTest(SuiteRunner.java:387)
	at org.testng.SuiteRunner.runSequentially(SuiteRunner.java:382)
	at org.testng.SuiteRunner.privateRun(SuiteRunner.java:340)
	at org.testng.SuiteRunner.run(SuiteRunner.java:289)
	at org.testng.SuiteRunnerWorker.runSuite(SuiteRunnerWorker.java:52)
	at org.testng.SuiteRunnerWorker.run(SuiteRunnerWorker.java:86)
	at org.testng.TestNG.runSuitesSequentially(TestNG.java:1293)
	at org.testng.TestNG.runSuitesLocally(TestNG.java:1218)
	at org.testng.TestNG.runSuites(TestNG.java:1133)
	at org.testng.TestNG.run(TestNG.java:1104)
	at org.testng.remote.AbstractRemoteTestNG.run(AbstractRemoteTestNG.java:132)
	at org.testng.remote.RemoteTestNG.initAndRun(RemoteTestNG.java:236)
	at org.testng.remote.RemoteTestNG.main(RemoteTestNG.java:81)
]]>
    </failure>
  </testcase> <!-- run_Test_ValidSizeParams_ValidArguments_Negative -->
  <testcase name="commandWithTimer_Test_ValidArguments_Negative" time="0.813" classname="CommandTest.CommandCheckContainsTest">
    <failure type="java.lang.AssertionError" message="expected [null] but found [! [checkPageContainsText &quot;I think this page do not have this text&quot;] 0,000]">
      <![CDATA[java.lang.AssertionError: expected [null] but found [! [checkPageContainsText "I think this page do not have this text"] 0,000]
	at org.testng.Assert.fail(Assert.java:94)
	at org.testng.Assert.failNotEquals(Assert.java:513)
	at org.testng.Assert.assertEqualsImpl(Assert.java:130)
	at org.testng.Assert.assertEquals(Assert.java:116)
	at org.testng.Assert.assertEquals(Assert.java:179)
	at CommandTest.CommandCheckContainsTest.commandWithTimer_Test_ValidArguments_Negative(CommandCheckContainsTest.java:134)
	at sun.reflect.NativeMethodAccessorImpl.invoke0(Native Method)
	at sun.reflect.NativeMethodAccessorImpl.invoke(Unknown Source)
	at sun.reflect.DelegatingMethodAccessorImpl.invoke(Unknown Source)
	at java.lang.reflect.Method.invoke(Unknown Source)
	at org.testng.internal.MethodInvocationHelper.invokeMethod(MethodInvocationHelper.java:104)
	at org.testng.internal.Invoker.invokeMethod(Invoker.java:645)
	at org.testng.internal.Invoker.invokeTestMethod(Invoker.java:851)
	at org.testng.internal.Invoker.invokeTestMethods(Invoker.java:1177)
	at org.testng.internal.TestMethodWorker.invokeTestMethods(TestMethodWorker.java:129)
	at org.testng.internal.TestMethodWorker.run(TestMethodWorker.java:112)
	at org.testng.TestRunner.privateRun(TestRunner.java:756)
	at org.testng.TestRunner.run(TestRunner.java:610)
	at org.testng.SuiteRunner.runTest(SuiteRunner.java:387)
	at org.testng.SuiteRunner.runSequentially(SuiteRunner.java:382)
	at org.testng.SuiteRunner.privateRun(SuiteRunner.java:340)
	at org.testng.SuiteRunner.run(SuiteRunner.java:289)
	at org.testng.SuiteRunnerWorker.runSuite(SuiteRunnerWorker.java:52)
	at org.testng.SuiteRunnerWorker.run(SuiteRunnerWorker.java:86)
	at org.testng.TestNG.runSuitesSequentially(TestNG.java:1293)
	at org.testng.TestNG.runSuitesLocally(TestNG.java:1218)
	at org.testng.TestNG.runSuites(TestNG.java:1133)
	at org.testng.TestNG.run(TestNG.java:1104)
	at org.testng.remote.AbstractRemoteTestNG.run(AbstractRemoteTestNG.java:132)
	at org.testng.remote.RemoteTestNG.initAndRun(RemoteTestNG.java:236)
	at org.testng.remote.RemoteTestNG.main(RemoteTestNG.java:81)
]]>
    </failure>
  </testcase> <!-- commandWithTimer_Test_ValidArguments_Negative -->
  <testcase name="run_Test_ValidSizeParams_EmptyString" time="0.078" classname="CommandTest.CommandCheckContainsTest"/>
  <testcase name="validateParams_Test_NotEnoughArguments" time="0.097" classname="CommandTest.CommandCheckContainsTest">
    <error type="org.testng.TestException" message="
Method CommandCheckContainsTest.validateParams_Test_NotEnoughArguments()[pri:0, instance:CommandTest.CommandCheckContainsTest@19f379] should have thrown an exception of type class java.lang.IllegalArgumentException">
      <![CDATA[org.testng.TestException: 
Method CommandCheckContainsTest.validateParams_Test_NotEnoughArguments()[pri:0, instance:CommandTest.CommandCheckContainsTest@19f379] should have thrown an exception of type class java.lang.IllegalArgumentException
	at org.testng.internal.ExpectedExceptionsHolder.noException(ExpectedExceptionsHolder.java:89)
	at org.testng.internal.Invoker.handleInvocationResults(Invoker.java:1401)
	at org.testng.internal.Invoker.invokeMethod(Invoker.java:684)
	at org.testng.internal.Invoker.invokeTestMethod(Invoker.java:851)
	at org.testng.internal.Invoker.invokeTestMethods(Invoker.java:1177)
	at org.testng.internal.TestMethodWorker.invokeTestMethods(TestMethodWorker.java:129)
	at org.testng.internal.TestMethodWorker.run(TestMethodWorker.java:112)
	at org.testng.TestRunner.privateRun(TestRunner.java:756)
	at org.testng.TestRunner.run(TestRunner.java:610)
	at org.testng.SuiteRunner.runTest(SuiteRunner.java:387)
	at org.testng.SuiteRunner.runSequentially(SuiteRunner.java:382)
	at org.testng.SuiteRunner.privateRun(SuiteRunner.java:340)
	at org.testng.SuiteRunner.run(SuiteRunner.java:289)
	at org.testng.SuiteRunnerWorker.runSuite(SuiteRunnerWorker.java:52)
	at org.testng.SuiteRunnerWorker.run(SuiteRunnerWorker.java:86)
	at org.testng.TestNG.runSuitesSequentially(TestNG.java:1293)
	at org.testng.TestNG.runSuitesLocally(TestNG.java:1218)
	at org.testng.TestNG.runSuites(TestNG.java:1133)
	at org.testng.TestNG.run(TestNG.java:1104)
	at org.testng.remote.AbstractRemoteTestNG.run(AbstractRemoteTestNG.java:132)
	at org.testng.remote.RemoteTestNG.initAndRun(RemoteTestNG.java:236)
	at org.testng.remote.RemoteTestNG.main(RemoteTestNG.java:81)
]]>
    </error>
  </testcase> <!-- validateParams_Test_NotEnoughArguments -->
  <testcase name="run_Test_ValidSizeParams_NullArguments" time="0.085" classname="CommandTest.CommandCheckContainsTest"/>
  <testcase name="commandWithTimer_Test_NullArguments" time="0.163" classname="CommandTest.CommandCheckContainsTest"/>
  <testcase name="validateParams_Test_Null_Document" time="1.684" classname="CommandTest.CommandCheckContainsTest">
    <error type="org.testng.TestException" message="
Method CommandCheckContainsTest.validateParams_Test_Null_Document()[pri:0, instance:CommandTest.CommandCheckContainsTest@19f379] should have thrown an exception of type class java.lang.IllegalStateException">
      <![CDATA[org.testng.TestException: 
Method CommandCheckContainsTest.validateParams_Test_Null_Document()[pri:0, instance:CommandTest.CommandCheckContainsTest@19f379] should have thrown an exception of type class java.lang.IllegalStateException
	at org.testng.internal.ExpectedExceptionsHolder.noException(ExpectedExceptionsHolder.java:89)
	at org.testng.internal.Invoker.handleInvocationResults(Invoker.java:1401)
	at org.testng.internal.Invoker.invokeMethod(Invoker.java:684)
	at org.testng.internal.Invoker.invokeTestMethod(Invoker.java:851)
	at org.testng.internal.Invoker.invokeTestMethods(Invoker.java:1177)
	at org.testng.internal.TestMethodWorker.invokeTestMethods(TestMethodWorker.java:129)
	at org.testng.internal.TestMethodWorker.run(TestMethodWorker.java:112)
	at org.testng.TestRunner.privateRun(TestRunner.java:756)
	at org.testng.TestRunner.run(TestRunner.java:610)
	at org.testng.SuiteRunner.runTest(SuiteRunner.java:387)
	at org.testng.SuiteRunner.runSequentially(SuiteRunner.java:382)
	at org.testng.SuiteRunner.privateRun(SuiteRunner.java:340)
	at org.testng.SuiteRunner.run(SuiteRunner.java:289)
	at org.testng.SuiteRunnerWorker.runSuite(SuiteRunnerWorker.java:52)
	at org.testng.SuiteRunnerWorker.run(SuiteRunnerWorker.java:86)
	at org.testng.TestNG.runSuitesSequentially(TestNG.java:1293)
	at org.testng.TestNG.runSuitesLocally(TestNG.java:1218)
	at org.testng.TestNG.runSuites(TestNG.java:1133)
	at org.testng.TestNG.run(TestNG.java:1104)
	at org.testng.remote.AbstractRemoteTestNG.run(AbstractRemoteTestNG.java:132)
	at org.testng.remote.RemoteTestNG.initAndRun(RemoteTestNG.java:236)
	at org.testng.remote.RemoteTestNG.main(RemoteTestNG.java:81)
]]>
    </error>
  </testcase> <!-- validateParams_Test_Null_Document -->
  <testcase name="validateParams_Test_ToManyArguments" time="0.067" classname="CommandTest.CommandCheckContainsTest">
    <error type="org.testng.TestException" message="
Method CommandCheckContainsTest.validateParams_Test_ToManyArguments()[pri:0, instance:CommandTest.CommandCheckContainsTest@19f379] should have thrown an exception of type class java.lang.IllegalArgumentException">
      <![CDATA[org.testng.TestException: 
Method CommandCheckContainsTest.validateParams_Test_ToManyArguments()[pri:0, instance:CommandTest.CommandCheckContainsTest@19f379] should have thrown an exception of type class java.lang.IllegalArgumentException
	at org.testng.internal.ExpectedExceptionsHolder.noException(ExpectedExceptionsHolder.java:89)
	at org.testng.internal.Invoker.handleInvocationResults(Invoker.java:1401)
	at org.testng.internal.Invoker.invokeMethod(Invoker.java:684)
	at org.testng.internal.Invoker.invokeTestMethod(Invoker.java:851)
	at org.testng.internal.Invoker.invokeTestMethods(Invoker.java:1177)
	at org.testng.internal.TestMethodWorker.invokeTestMethods(TestMethodWorker.java:129)
	at org.testng.internal.TestMethodWorker.run(TestMethodWorker.java:112)
	at org.testng.TestRunner.privateRun(TestRunner.java:756)
	at org.testng.TestRunner.run(TestRunner.java:610)
	at org.testng.SuiteRunner.runTest(SuiteRunner.java:387)
	at org.testng.SuiteRunner.runSequentially(SuiteRunner.java:382)
	at org.testng.SuiteRunner.privateRun(SuiteRunner.java:340)
	at org.testng.SuiteRunner.run(SuiteRunner.java:289)
	at org.testng.SuiteRunnerWorker.runSuite(SuiteRunnerWorker.java:52)
	at org.testng.SuiteRunnerWorker.run(SuiteRunnerWorker.java:86)
	at org.testng.TestNG.runSuitesSequentially(TestNG.java:1293)
	at org.testng.TestNG.runSuitesLocally(TestNG.java:1218)
	at org.testng.TestNG.runSuites(TestNG.java:1133)
	at org.testng.TestNG.run(TestNG.java:1104)
	at org.testng.remote.AbstractRemoteTestNG.run(AbstractRemoteTestNG.java:132)
	at org.testng.remote.RemoteTestNG.initAndRun(RemoteTestNG.java:236)
	at org.testng.remote.RemoteTestNG.main(RemoteTestNG.java:81)
]]>
    </error>
  </testcase> <!-- validateParams_Test_ToManyArguments -->
  <testcase name="commandWithTimer_Test_ValidSizeParams_EmptyString" time="0.081" classname="CommandTest.CommandCheckContainsTest">
    <error type="java.lang.ArrayIndexOutOfBoundsException" message="0">
      <![CDATA[java.lang.ArrayIndexOutOfBoundsException: 0
	at com.klindziuk.framework.command.Command.validateParams(Command.java:35)
	at com.klindziuk.framework.command.Command.validateParamsAndDocument(Command.java:54)
	at com.klindziuk.framework.command.CommandCheckContainsText.run(CommandCheckContainsText.java:12)
	at com.klindziuk.framework.command.Command.runWithTimer(Command.java:27)
	at CommandTest.CommandCheckContainsTest.commandWithTimer_Test_ValidSizeParams_EmptyString(CommandCheckContainsTest.java:149)
	at sun.reflect.NativeMethodAccessorImpl.invoke0(Native Method)
	at sun.reflect.NativeMethodAccessorImpl.invoke(Unknown Source)
	at sun.reflect.DelegatingMethodAccessorImpl.invoke(Unknown Source)
	at java.lang.reflect.Method.invoke(Unknown Source)
	at org.testng.internal.MethodInvocationHelper.invokeMethod(MethodInvocationHelper.java:104)
	at org.testng.internal.Invoker.invokeMethod(Invoker.java:645)
	at org.testng.internal.Invoker.invokeTestMethod(Invoker.java:851)
	at org.testng.internal.Invoker.invokeTestMethods(Invoker.java:1177)
	at org.testng.internal.TestMethodWorker.invokeTestMethods(TestMethodWorker.java:129)
	at org.testng.internal.TestMethodWorker.run(TestMethodWorker.java:112)
	at org.testng.TestRunner.privateRun(TestRunner.java:756)
	at org.testng.TestRunner.run(TestRunner.java:610)
	at org.testng.SuiteRunner.runTest(SuiteRunner.java:387)
	at org.testng.SuiteRunner.runSequentially(SuiteRunner.java:382)
	at org.testng.SuiteRunner.privateRun(SuiteRunner.java:340)
	at org.testng.SuiteRunner.run(SuiteRunner.java:289)
	at org.testng.SuiteRunnerWorker.runSuite(SuiteRunnerWorker.java:52)
	at org.testng.SuiteRunnerWorker.run(SuiteRunnerWorker.java:86)
	at org.testng.TestNG.runSuitesSequentially(TestNG.java:1293)
	at org.testng.TestNG.runSuitesLocally(TestNG.java:1218)
	at org.testng.TestNG.runSuites(TestNG.java:1133)
	at org.testng.TestNG.run(TestNG.java:1104)
	at org.testng.remote.AbstractRemoteTestNG.run(AbstractRemoteTestNG.java:132)
	at org.testng.remote.RemoteTestNG.initAndRun(RemoteTestNG.java:236)
	at org.testng.remote.RemoteTestNG.main(RemoteTestNG.java:81)
]]>
    </error>
  </testcase> <!-- commandWithTimer_Test_ValidSizeParams_EmptyString -->
  <testcase name="run_Test_ValidSizeParams_ValidArguments_Positive" time="0.075" classname="CommandTest.CommandCheckContainsTest">
    <failure type="java.lang.AssertionError" message="expected [+ [checkPageContainsText &quot;Software Automation Tester&quot;] 0,000] but found [+ [checkPageContains &quot;Software Automation Tester&quot;] 0,000]">
      <![CDATA[java.lang.AssertionError: expected [+ [checkPageContainsText "Software Automation Tester"] 0,000] but found [+ [checkPageContains "Software Automation Tester"] 0,000]
	at org.testng.Assert.fail(Assert.java:94)
	at org.testng.Assert.failNotEquals(Assert.java:513)
	at org.testng.Assert.assertEqualsImpl(Assert.java:135)
	at org.testng.Assert.assertEquals(Assert.java:116)
	at org.testng.Assert.assertEquals(Assert.java:179)
	at CommandTest.CommandCheckContainsTest.run_Test_ValidSizeParams_ValidArguments_Positive(CommandCheckContainsTest.java:60)
	at sun.reflect.NativeMethodAccessorImpl.invoke0(Native Method)
	at sun.reflect.NativeMethodAccessorImpl.invoke(Unknown Source)
	at sun.reflect.DelegatingMethodAccessorImpl.invoke(Unknown Source)
	at java.lang.reflect.Method.invoke(Unknown Source)
	at org.testng.internal.MethodInvocationHelper.invokeMethod(MethodInvocationHelper.java:104)
	at org.testng.internal.Invoker.invokeMethod(Invoker.java:645)
	at org.testng.internal.Invoker.invokeTestMethod(Invoker.java:851)
	at org.testng.internal.Invoker.invokeTestMethods(Invoker.java:1177)
	at org.testng.internal.TestMethodWorker.invokeTestMethods(TestMethodWorker.java:129)
	at org.testng.internal.TestMethodWorker.run(TestMethodWorker.java:112)
	at org.testng.TestRunner.privateRun(TestRunner.java:756)
	at org.testng.TestRunner.run(TestRunner.java:610)
	at org.testng.SuiteRunner.runTest(SuiteRunner.java:387)
	at org.testng.SuiteRunner.runSequentially(SuiteRunner.java:382)
	at org.testng.SuiteRunner.privateRun(SuiteRunner.java:340)
	at org.testng.SuiteRunner.run(SuiteRunner.java:289)
	at org.testng.SuiteRunnerWorker.runSuite(SuiteRunnerWorker.java:52)
	at org.testng.SuiteRunnerWorker.run(SuiteRunnerWorker.java:86)
	at org.testng.TestNG.runSuitesSequentially(TestNG.java:1293)
	at org.testng.TestNG.runSuitesLocally(TestNG.java:1218)
	at org.testng.TestNG.runSuites(TestNG.java:1133)
	at org.testng.TestNG.run(TestNG.java:1104)
	at org.testng.remote.AbstractRemoteTestNG.run(AbstractRemoteTestNG.java:132)
	at org.testng.remote.RemoteTestNG.initAndRun(RemoteTestNG.java:236)
	at org.testng.remote.RemoteTestNG.main(RemoteTestNG.java:81)
]]>
    </failure>
  </testcase> <!-- run_Test_ValidSizeParams_ValidArguments_Positive -->
  <testcase name="validateParams_Test_Null_params" time="0.090" classname="CommandTest.CommandCheckContainsTest">
    <error type="org.testng.TestException" message="
Method CommandCheckContainsTest.validateParams_Test_Null_params()[pri:0, instance:CommandTest.CommandCheckContainsTest@19f379] should have thrown an exception of type class java.lang.NullPointerException">
      <![CDATA[org.testng.TestException: 
Method CommandCheckContainsTest.validateParams_Test_Null_params()[pri:0, instance:CommandTest.CommandCheckContainsTest@19f379] should have thrown an exception of type class java.lang.NullPointerException
	at org.testng.internal.ExpectedExceptionsHolder.noException(ExpectedExceptionsHolder.java:89)
	at org.testng.internal.Invoker.handleInvocationResults(Invoker.java:1401)
	at org.testng.internal.Invoker.invokeMethod(Invoker.java:684)
	at org.testng.internal.Invoker.invokeTestMethod(Invoker.java:851)
	at org.testng.internal.Invoker.invokeTestMethods(Invoker.java:1177)
	at org.testng.internal.TestMethodWorker.invokeTestMethods(TestMethodWorker.java:129)
	at org.testng.internal.TestMethodWorker.run(TestMethodWorker.java:112)
	at org.testng.TestRunner.privateRun(TestRunner.java:756)
	at org.testng.TestRunner.run(TestRunner.java:610)
	at org.testng.SuiteRunner.runTest(SuiteRunner.java:387)
	at org.testng.SuiteRunner.runSequentially(SuiteRunner.java:382)
	at org.testng.SuiteRunner.privateRun(SuiteRunner.java:340)
	at org.testng.SuiteRunner.run(SuiteRunner.java:289)
	at org.testng.SuiteRunnerWorker.runSuite(SuiteRunnerWorker.java:52)
	at org.testng.SuiteRunnerWorker.run(SuiteRunnerWorker.java:86)
	at org.testng.TestNG.runSuitesSequentially(TestNG.java:1293)
	at org.testng.TestNG.runSuitesLocally(TestNG.java:1218)
	at org.testng.TestNG.runSuites(TestNG.java:1133)
	at org.testng.TestNG.run(TestNG.java:1104)
	at org.testng.remote.AbstractRemoteTestNG.run(AbstractRemoteTestNG.java:132)
	at org.testng.remote.RemoteTestNG.initAndRun(RemoteTestNG.java:236)
	at org.testng.remote.RemoteTestNG.main(RemoteTestNG.java:81)
]]>
    </error>
  </testcase> <!-- validateParams_Test_Null_params -->
</testsuite> <!-- CommandTest.CommandCheckContainsTest -->
